Workbook

Sheet COVER PAGE
B1: Unilever Group
B3: FINANCIAL ANALYSIS | FMCG & CONSUMER PRODUCTS
B4: Project Overview
B6: PROJECT PROFILE | E6: PROJECT SCOPE
B7: Company | C7: Unilever Group | E7: Primary Focus | F7: Financial statement and ratio analysis
B8: Industry | C8: FMCG / Consumer Products | E8: Analysis Areas | F8: Profitability • Efficiency • Working Capital
B9: Analysis Period | C9: FY2020 – FY2021 | E9: Risk Areas | F9: Liquidity • Solvency • Capital structure
B10: Reporting Unit | C10: € million | E10: Output | F10: Financial performance dashboard
B11: Prepared By | C11: Ayush Nitin Jagtap
B12: Professional Focus | C12: AI - Integrated Finance | Accounting | Finance & Business Analysis | Financial Modeling
B13: Education | C13: B.Com (Business Administration) | M.Com ( Accounting, Analysis & Income Tax)
B14: Email ID | C14: ayushjagtap1657@gmail.com
B15: LinkedIn | C15: https://www.linkedin.com/in/ayush-jagtap-a14767278/?isSelfProfile=true
B16: ANALYTICAL FRAMEWORK
B17: 01 | C17: Financial Statements | E17: Income statement and balance sheet review.
B18: 02 | C18: Common-Size Analysis | E18: Structural analysis of statement composition.
B19: 03 | C19: Ratio Analysis | E19: Profitability, liquidity, solvency, efficiency and working capital.
B20: 04 | C20: Interpretation | E20: Year-on-year movement translated into business observations.
B21: 05 | C21: Dashboard | E21: Visual summary of financial performance and key takeaways.
B22: AI-ASSISTED ANALYTICAL WORKFLOW
B23: ChatGPT was used as an AI assistant during the project to support research, analytical structuring, financial concept and ratio understanding, interpretation drafting and presentation refinement. The underlying financial data, workbook calculations and final analytical judgement remain the project creator’s work.
B26: PROJECT DELIVERABLES
B27: ✓ Financial Statements
B28: ✓ Common-Size Financial Statements
B29: ✓ Ratio Calculations
B30: ✓ Ratio Interpretation
B31: ✓ Financial Performance Dashboard
B32: Portfolio project | Focus: structured financial analysis, business interpretation and AI-assisted analytical workflow

Sheet METHODOLOGY
B2: Unilever Group
B3: PROJECT OBJECTIVE
B5: SCOPE OF ANALYSIS
B6: • Consolidated Income Statement and Balance Sheet
B7: • Common-size income statement and balance sheet
B8: • Profitability ratios and margin analysis
B9: • Liquidity and solvency indicators
B10: • Efficiency and working-capital ratios
B11: • Year-on-year interpretation of movements
B13: METHODOLOGY
B14: 1. Organise the reported financial statement data for FY2020 and FY2021.
B15: 2. Calculate derived financial statement values using workbook formulas.
... B22: AI INTEGRATION
B23: AI assistant | C23: ChatGPT was used alongside Excel to support the analytical workflow.
B24: Research support | C24: Assisted with financial concepts, ratio definitions and analytical framing.
B25: Interpretation support | C25: Helped structure concise explanations of year-on-year financial movements.
B26: Presentation support | C26: Supported professional organisation of the project and dashboard narrative.
B27: Human validation | C27: Financial figures, workbook calculations, source data and final conclusions were reviewed and retained by the project creator.
B29: PROJECT OUTPUT
B30: The completed workbook contains the source financial statements, common-size analysis, ratio calculations, ratio interpretation and a financial performance dashboard. The analytical sequence moves from reported numbers → calculated metrics → interpretation → visual summary.

Sheet Financial Statement
A1: Unilever Group Financial Statement 2020 - 2021
B2: Consolidated Income Statement | G2: Consolidated Balance Sheet
B3: for the year ended 31st December | D3: Figures in € millions | G3: as at 31 December
C4: 2021 | D4: 2020 | I4: € million | J4: € million
B5: Revenue | C5: 52444 | D5: 50724 | I5: 2021 | J5: 2020
B6: Cost of sales | C6: 30259 | D6: 28684 | G6: Assets
B7: Gross profit | C7: =C5-C6 -> 22185 | D7: =D5-D6 -> 22040 | G7: Non-current assets
B8: Operating expenses | G8: Goodwill | I8: 20330 | J8: 18942
B9: Research and development costs | C9: 847 | D9: 800 | G9: Intangible assets | I9: 18261 | J9: 15999
B10: Selling, general and administrative expenses | C10: 6873 | D10: 7091 | G10: Property, plant and equipment | I10: 10347 | J10: 10558
B11: Other operating expenses | C11: =5676-847+934 -> 5763 | D11: =5582-800+1064 -> 5846 | G11: Pension asset for funded schemes in surplus | I11: 5119 | J11: 2722
B12: Total operating expenses | C12: =SUM(C9:C11) -> 13483 | D12: =SUM(D9:D11) -> 13737 | G12: Deferred tax assets | I12: 1465 | J12: 1474
B13: Operating profit (EBIT) | C13: =C7-C12 -> 8702 | D13: =D7-D12 -> 8303 | G13: Financial assets | I13: 1198 | J13: 876
B14: Net finance costs | C14: 354 | D14: 505 | G14: Other non-current assets | I14: 974 | J14: 931
B15: Share of net profit/(loss) of joint ventures and associates | C15: 191 | D15: 175 | I15: =SUM(I8:I14) -> 57694 | J15: =SUM(J8:J14) -> 51502
B16: Other income/(loss) from non-current investments and associates | C16: 91 | D16: 3 | G16: Current assets
B17: Non-underlying item net monetary gain/(loss) arising from hyperinflationary economies | C17: -74 | D17: 20 | G17: Inventories | I17: 4683 | J17: 4462
B18: Income before tax | C18: =C13-C14+C15+C16+C17 -> 8556 | D18: =D13-D14+D15+D16+D17 -> 7996 | G18: Trade and other current receivables | I18: 5422 | J18: 4939
B19: Income tax expense | C19: 1935 | D19: 1923 | G19: Current tax assets | I19: 324 | J19: 372
B20: Net Profit | C20: =C18-C19 -> 6621 | D20: =D18-D19 -> 6073 | G20: Cash and cash equivalents | I20: 3415 | J20: 5548
G21: Other financial assets | I21: 1156 | J21: 808
G22: Assets held for sale | I22: 2401 | J22: 28
I23: =SUM(I17:I22) -> 17401 | J23: =SUM(J17:J22) -> 16157
G24: Total assets | I24: =I23+I15 -> 75095 | J24: =J23+J15 -> 67659
G25: Liabilities
G26: Current liabilities
G27: Financial liabilities | I27: 7252 | J27: 4461
G28: Trade payables and other current liabilities | I28: 14861 | J28: 14132
G29: Current tax liabilities | I29: 1365 | J29: 1451
G30: Provisions | I30: 480 | J30: 547
G31: Liabilities held for sale | I31: 820 | J31: 1
I32: =SUM(I27:I31) -> 24778 | J32: =SUM(J27:J31) -> 20592
G33: Non-current liabilities
G34: Financial liabilities | I34: 22881 | J34: 22844
G35: Non-current tax liabilities | I35: 148 | J35: 149
G36: Pensions and post-retirement healthcare liabilities:
G37: Funded schemes in deficit | I37: 831 | J37: 1109
G38: Unfunded schemes | I38: 1295 | J38: 1326
G39: Provisions | I39: 611 | J39: 583
G40: Deferred tax liabilities | I40: 4530 | J40: 3166
...

Sheet Common Size Financial Statement
B1: Unilever Group Financial Statement 2020 - 2021
B2: Commen Size Income Statement | J2: Commen Size Balance Sheet
B3: for the year ended 31st December | E3: Figures in € millions | J3: as at 31 December
C4: 2021 | D4: Commen Size | E4: 2020 | F4: Commen Size | G4: Difference in % | L4: € million | M4: Commen | N4: € million | O4: Commen | P4: Difference in
B5: Revenue | C5: 52444 | D5: 1 | E5: 50724 | F5: 1 | G5: =F5-D5 -> 0 | L5: 2021 | M5: Size | N5: 2020 | O5: Size | P5: %
B6: Cost of sales | C6: 30259 | D6: =C6/C5% -> 57.697735 | E6: 28684 | F6: =E6/E5 -> 0.56549168 | G6: =F6/D6 -> 0.0098009338 | J6: Assets
B7: Gross profit | C7: =C5-C6 -> 22185 | D7: =C7/$C$5 -> 0.42302265 | E7: =E5-E6 -> 22040 | F7: =E7/$E$5 -> 0.43450832 | G7: =F7-D7 -> 0.011485667 | J7: Non-current assets
B8: Operating expenses | F8: =E8/$E$5 -> 0 | J8: Goodwill | L8: 20330 | M8: =L8/$L$24 -> 0.27072375 | N8: 18942 | O8: =N8/$N$24 -> 0.27996275 | P8: {=O8:O23-M8:M23} -> 0.0092390045
B9: Research and development costs | C9: 847 | D9: =C9/$C$5 -> 0.016150561 | E9: 800 | F9: =E9/$E$5 -> 0.015771627 | G9: =F9-D9 -> -0.00037893375 | J9: Intangible assets | L9: 18261 | M9: =L9/$L$24 -> 0.24317198 | N9: 15999 | O9: =N9/$N$24 -> 0.23646522 | P9: -0.0067067669
B10: Selling, general and administrative expenses | C10: 6873 | D10: =C10/$C$5 -> 0.13105408 | E10: 7091 | F10: =E10/$E$5 -> 0.13979576 | G10: =F10-D10 -> 0.0087416807 | J10: Property, plant and equipment | L10: 10347 | M10: =L10/$L$24 -> 0.13778547 | N10: 10558 | O10: =N10/$N$24 -> 0.15604724 | P10: 0.018261765
B11: Other operating expenses | C11: =5676-847+934 -> 5763 | D11: =C11/$C$5 -> 0.10988864 | E11: =5582-800+1064 -> 5846 | F11: =E11/$E$5 -> 0.11525116 | G11: =F11-D11 -> 0.00536252 | J11: Pension asset for funded schemes in surplus | L11: 5119 | M11: =L11/$L$24 -> 0.068166988 | N11: 2722 | O11: =N11/$N$24 -> 0.040231159 | P11: -0.027935829
B12: Total operating expenses | C12: =SUM(C9:C11) -> 13483 | D12: =C12/$C$5 -> 0.25709328 | E12: =SUM(E9:E11) -> 13737 | F12: =E12/$E$5 -> 0.27081855 | G12: =F12-D12 -> 0.013725267 | J12: Deferred tax assets | L12: 1465 | M12: =L12/$L$24 -> 0.019508622 | N12: 1474 | O12: =N12/$N$24 -> 0.02178572 | P12: 0.0022770972
B13: Operating profit (EBIT) | C13: =C7-C12 -> 8702 | D13: =C13/$C$5 -> 0.16592937 | E13: =E7-E12 -> 8303 | F13: =E13/$E$5 -> 0.16368977 | G13: =F13-D13 -> -0.0022396002 | J13: Financial assets | L13: 1198 | M13: =L13/$L$24 -> 0.015953126 | N13: 876 | O13: =N13/$N$24 -> 0.01294728 | P13: -0.0030058463
B14: Net finance costs | C14: 354 | D14: =C14/$C$5 -> 0.0067500572 | E14: 505 | F14: =E14/$E$5 -> 0.0099558394 | G14: =F14-D14 -> 0.0032057822 | J14: Other non-current assets | L14: 974 | M14: =L14/$L$24 -> 0.012970238 | N14: 931 | O14: =N14/$N$24 -> 0.01376018 | P14: 0.00078994203
B15: Share of net profit/(loss) of joint ventures and associates | C15: 191 | D15: =C15/$C$5 -> 0.00364198 | E15: 175 | F15: =E15/$E$5 -> 0.0034500434 | G15: =F15-D15 -> -0.00019193664 | L15: =SUM(L8:L14) -> 57694 | M15: =L15/$L$24 -> 0.76828018 | N15: =SUM(N8:N14) -> 51502 | O15: =N15/$N$24 -> 0.76119954 | P15: -0.0070806337
B16: Other income/(loss) from non-current investments and associates | C16: 91 | D16: =C16/$C$5 -> 0.0017351842 | E16: 3 | F16: =E16/$E$5 -> 5.9143601e-05 | G16: =F16-D16 -> -0.0016760406 | J16: Current assets | M16: =L16/$L$24 -> 0 | O16: =N16/$N$24 -> 0 | P16: 0
B17: Non-underlying item net monetary gain/(loss) arising from hyperinflationary economies | C17: -74 | D17: =C17/$C$5 -> -0.0014110289 | E17: 20 | F17: =E17/$E$5 -> 0.00039429067 | G17: =F17-D17 -> 0.0018053196 | J17: Inventories | L17: 4683 | M17: =L17/$L$24 -> 0.062361009 | N17: 4462 | O17: =N17/$N$24 -> 0.065948359 | P17: 0.0035873493
B18: Income before tax | C18: =C13-C14+C15+C16+C17 -> 8556 | D18: =C18/$C$5 -> 0.16314545 | E18: =E13-E14+E15+E16+E17 -> 7996 | F18: =E18/$E$5 -> 0.15763741 | G18: =F18-D18 -> -0.0055080401 | J18: Trade and other current receivables | L18: 5422 | M18: =L18/$L$24 -> 0.072201878 | N18: 4939 | O18: =N18/$N$24 -> 0.072998419 | P18: 0.00079654092
B19: Income tax expense | C19: 1935 | D19: =C19/$C$5 -> 0.036896499 | E19: 1923 | F19: =E19/$E$5 -> 0.037911048 | G19: =F19-D19 -> 0.0010145489 | J19: Current tax assets | L19: 324 | M19: =L19/$L$24 -> 0.0043145349 | N19: 372 | O19: =N19/$N$24 -> 0.0054981599 | P19: 0.001183625
B20: Net Profit | C20: =C18-C19 -> 6621 | D20: =C20/$C$5 -> 0.12624895 | E20: =E18-E19 -> 6073 | F20: =E20/$E$5 -> 0.11972636 | G20: =F20-D20 -> -0.006522589 | J20: Cash and cash equivalents | L20: 3415 | M20: =L20/$L$24 -> 0.045475731 | N20: 5548 | O20: =N20/$N$24 -> 0.081999438 | P20: 0.036523708
J21: Other financial assets | L21: 1156 | M21: =L21/$L$24 -> 0.015393834 | N21: 808 | O21: =N21/$N$24 -> 0.01194224 | P21: -0.0034515947
J22: Assets held for sale | L22: 2401 | M22: =L22/$L$24 -> 0.031972834 | N22: 28 | O22: =N22/$N$24 -> 0.00041383999 | P22: -0.031558994
L23: =SUM(L17:L22) -> 17401 | M23: =L23/$L$24 -> 0.23171982 | N23: =SUM(N17:N22) -> 16157 | O23: =N23/$N$24 -> 0.23880046 | P23: 0.0070806337
J24: Total assets | L24: =L23+L15 -> 75095 | M24: 1 | N24: =N23+N15 -> 67659 | O24: 1 | P24: =O24-M24 -> 0
J25: Liabilities
J26: Current liabilities
J27: Financial liabilities | L27: 7252 | M27: =L27/$L$48 -> 0.09657101 | N27: 4461 | O27: =N27/$N$48 -> 0.065933579 | P27: =O27-M27 -> -0.030637431
J28: Trade payables and other current liabilities | L28: 14861 | M28: =L28/$L$48 -> 0.197896 | N28: 14132 | O28: =N28/$N$48 -> 0.20887096 | P28: =O28-M28 -> 0.010974957
J29: Current tax liabilities | L29: 1365 | M29: =L29/$L$48 -> 0.018176976 | N29: 1451 | O29: =N29/$N$48 -> 0.02144578 | P29: =O29-M29 -> 0.0032688037
J30: Provisions | L30: 480 | M30: =L30/$L$48 -> 0.0063919036 | N30: 547 | O30: =N30/$N$48 -> 0.0080846598 | P30: =O30-M30 -> 0.0016927562
J31: Liabilities held for sale | L31: 820 | M31: =L31/$L$48 -> 0.010919502 | N31: 1 | O31: =N31/$N$48 -> 1.478e-05 | P31: =O31-M31 -> -0.010904722
L32: =SUM(L27:L31) -> 24778 | M32: =L32/$L$48 -> 0.32995539 | N32: =SUM(N27:N31) -> 20592 | O32: =N32/$N$48 -> 0.30434975 | P32: =O32-M32 -> -0.025605636
J33: Non-current liabilities | M33: =L33/$L$48 -> 0 | O33: =N33/$N$48 -> 0
J34: Financial liabilities | L34: 22881 | M34: =L34/$L$48 -> 0.30469405 | N34: 22844 | O34: =N34/$N$48 -> 0.33763431 | P34: {=O34:O41-M34:M41} -> 0.032940259
J35: Non-current tax liabilities | L35: 148 | M35: =L35/$L$48 -> 0.0019708369 | N35: 149 | O35: =N35/$N$48 -> 0.00220222 | P35: 0.00023138302
J36: Pensions and post-retirement healthcare liabilities: | M36: =L36/$L$48 -> 0 | O36: =N36/$N$48 -> 0 | P36: 0
J37: Funded schemes in deficit | L37: 831 | M37: =L37/$L$48 -> 0.011065983 | N37: 1109 | O37: =N37/$N$48 -> 0.01639102 | P37: 0.0053250366
J38: Unfunded schemes | L38: 1295 | M38: =L38/$L$48 -> 0.017244823 | N38: 1326 | O38: =N38/$N$48 -> 0.01959828 | P38: 0.0023534564
J39: Provisions | L39: 611 | M39: =L39/$L$48 -> 0.0081363606 | N39: 583 | O39: =N39/$N$48 -> 0.0086167398 | P39: 0.00048037922
J40: Deferred tax liabilities | L40: 4530 | M40: =L40/$L$48 -> 0.06032359 | N40: 3166 | O40: =N40/$N$48 -> 0.046793479 | P40: -0.013530111
...

Sheet Ratios Analysis
D1: Unilever Group Financial ratio
AL4: 4 | AM4: Return on Investment
AM5: Return on Assets (ROA) | AS5: Figures In Million | BH5: Return on Capital Employed (ROCE) | BN5: Figures In Million
AS6: 2021 | AU6: 2020 | BN6: 2021 | BP6: 2020
AW7: 2021 :- | AX7: 75,095 (Assets 2021)+67,659 (Assets 2020)​ = 142,754​ = 71,377 | BD7: }
AM8: Total Assets | AS8: ='Common Size Financial Statement'!L24 -> 75095 | AU8: ='Common Size Financial Statement'!N24 -> 67659 | BB8: 2 | BE8: Average Assets
AM9: Net Profit | AS9: ='Common Size Financial Statement'!C20 -> 6621 | AU9: ='Common Size Financial Statement'!E20 -> 6073 | AW9: 2020 :- | AX9: 67,659 (Assets 2020)+64,806 (Assets 2019)​ = 132,465 ​= 66,233 | BH9: EBIT | BN9: ='Common Size Financial Statement'!C13 -> 8702 | BP9: ='Common Size Financial Statement'!E13 -> 8303
C10: 1 | D10: Profitability Ratio | AM10: Total Average Assets | AS10: =142754/2 -> 71377 | AU10: 66233 | BA10: 2 | BH10: Capital Employed (Total Assets – Current Liabilities) | BN10: ='Common Size Financial Statement'!L24-'Common Size Financial Statement'!L32 -> 50317 | BP10: ='Common Size Financial Statement'!N24-'Common Size Financial Statement'!N32 -> 47067
D11: Gross Profit Margin | J11: Figures In Million | P11: Operating Margin | V11: Figures In Million | AA11: Net Profit Margin | AG11: Figures In Million
AA12: Operational efficency of business | AO12: Net Profit/Total assets | AS12: =AS9/AS10 -> 0.092760973 | AU12: =AU9/AU10 -> 0.091691453 | BJ12: EBIT/Capital Employed | BN12: =BN9/BN10 -> 0.17294354 | BP12: =BP9/BP10 -> 0.1764081
J13: 2021 | L13: 2020 | V13: 2021 | X13: 2020 | AG13: 2021 | AI13: 2020
D15: Gross Profit | J15: ='Common Size Financial Statement'!C7 -> 22185 | L15: ='Common Size Financial Statement'!E7 -> 22040 | P15: Operating Profit | V15: ='Common Size Financial Statement'!C13 -> 8702 | X15: ='Common Size Financial Statement'!E13 -> 8303 | AA15: Net Profit | AG15: ='Common Size Financial Statement'!C20 -> 6621 | AI15: ='Common Size Financial Statement'!E20 -> 6073
D16: Revenue | J16: ='Common Size Financial Statement'!C5 -> 52444 | L16: ='Common Size Financial Statement'!E5 -> 50724 | P16: Revenue | V16: ='Common Size Financial Statement'!C5 -> 52444 | X16: ='Common Size Financial Statement'!E5 -> 50724 | AA16: Revenue | AG16: =V16 -> 52444 | AI16: =X16 -> 50724
AM17: Return on Equity (ROE) | AS17: Figures In Million
D18: Gross Profit Margin | G18: Gross Profit/ Revenue | J18: =J15/J16 -> 0.42302265 | L18: =L15/L16 -> 0.43450832 | P18: Operating Profit Margin | S18: Operating Profit/ Revenue | V18: =V15/V16 -> 0.16592937 | X18: =X15/X16 -> 0.16368977 | AA18: Net Profit Margin | AD18: Net Profit/ Revenue | AG18: =AG15/AG16 -> 0.12624895 | AI18: =AI15/AI16 -> 0.11972636 | AS18: 2021 | AU18: 2020
AM20: Equity | AS20: 19746 | AU20: 17655 | AW20: 2021 :- | AX20: 9,746 (Equity 2021)+17,655 (Equity 2020)​= 37,401 ​= 18,701 | BD20: }
AM21: Net Profit | AS21: 6621 | AU21: 6073 | BB21: 2 | BE21: Average Equity
AM22: Average Equity | AS22: 18701 | AU22: 15771 | AW22: 2020 :- | AX22: 217,655 (Equity 2020)+13,886 (Equity 2019)​= 31,541 ​= 15,771
C23: 2 | D23: Liquidity ratio | BB23: 2
D24: Current ratio (Short-term Liq. Position) | J24: Figures In Million | P24: Quick ratio / Acid test ratio | V24: Figures In Million | AA24: Payable turnover ratio | AG24: Figures In Million | AO24: Net Profit/ Average Equity | AS24: =AS21/AS22 -> 0.35404524 | AU24: =AU21/AU22 -> 0.38507387
J25: 2021 | L25: 2020 | P25: (Short-term Liq. Position) | V25: 2021 | X25: 2020 | AG25: 2021 | AI25: 2020
D28: Current Assets | J28: ='Common Size Financial Statement'!L23 -> 17401 | L28: ='Common Size Financial Statement'!N23 -> 16157 | P28: Current Assets - Inventory | V28: ='Common Size Financial Statement'!L23-'Common Size Financial Statement'!L17 -> 12718 | X28: ='Common Size Financial Statement'!N23-'Common Size Financial Statement'!N17 -> 11695 | AA28: Total suppliers purches / COGS | AG28: ='Common Size Financial Statement'!C6 -> 30259 | AI28: ='Common Size Financial Statement'!E6 -> 28684 | AM28: Assets Utilization Ratio | AS28: Figures In Million
D29: Current liabilitity | J29: ='Common Size Financial Statement'!L32 -> 24778 | L29: ='Common Size Financial Statement'!N32 -> 20592 | P29: Current liabilitity | V29: =J29 -> 24778 | X29: ='Common Size Financial Statement'!N32 -> 20592 | AA29: Average Accounts / Trade payable | AG29: =AH35/2 -> 14496.5 | AI29: =AI35/2 -> 13913.5 | AS29: 2021 | AU29: 2020
AW30: 2021 :- | AX30: 75,095 (Assets 2021)+67,659 (Assets 2020)​ = 142,754​ = 71,377 | BD30: }
F31: CA/CL | J31: =J28/J29 -> 0.70227621 | L31: =L28/L29 -> 0.7846251 | R31: CA/CL | V31: =V28/V29 -> 0.51327791 | X31: =X28/X29 -> 0.56793901 | AG31: =AG28/AG29/100 -> 0.020873314 | AI31: =AI28/AI29/100 -> 0.020615949 | BB31: 2 | BE31: Average Assets
AM32: Revenue | AS32: ='Common Size Financial Statement'!C5 -> 52444 | AU32: ='Common Size Financial Statement'!E5 -> 50724 | AW32: 2020 :- | AX32: 67,659 (Assets 2020)+64,806 (Assets 2019)​ = 132,465 ​= 66,233
AD33: Days Payable Outstanding | AH33: Trade payable calculation | AM33: Average Total Assets | AS33: =AS10 -> 71377 | AU33: =AU10 -> 66233 | BA33: 2
AH34: 2021 | AI34: 2020
AA35: Days Payable Outstanding = | AD35: 365 | AH35: ='Common Size Financial Statement'!L28+'Common Size Financial Statement'!N28 -> 28993 | AI35: ='Common Size Financial Statement'!N28+13695 -> 27827 | AO35: Revenue / Total Average Assets | AS35: =AS32/AS33 -> 0.73474649 | AU35: =AU32/AU33 -> 0.7658418
AD36: Payable turnover ratio
C41: 3 | D41: Solvency Ratio | AL41: 5 | AM41: Turnover Ratios
D42: Long-term Debt–Equity Ratio | J42: Figures In Million | O42: Liabilities to Assets Ratio | U42: Figures In Million | Y42: Intrest coverage ratio | AE42: Figures In Million | AM42: Total Assets turnover Ratio | AS42: Figures In Million | AX42: FA Turnover Ratio | BD42: Figures In Million
D43: (Long-term Liq. Position) | Y43: (Long-term Liq. Position) | AM43: Overall efficency of business | AS43: 2021 | AU43: 2020 | AV43: 2019 | BD43: 2021 | BF43: 2020 | BG43: 2019
J44: 2021 | L44: 2020 | U44: 2021 | W44: 2020 | AE44: 2021 | AG44: 2020 | AM44: Total Assets | AS44: ='Common Size Financial Statement'!L48 -> 75095 | AU44: ='Common Size Financial Statement'!N48 -> 67659 | AV44: 64806 | AX44: ='Common Size Financial Statement'!J10 -> Property, plant and equipment | BD44: ='Common Size Financial Statement'!L10 -> 10347 | BF44: ='Common Size Financial Statement'!N10 -> 10558 | BG44: 12062
AM45: Revenue | AS45: ='Common Size Financial Statement'!C5 -> 52444 | AU45: ='Common Size Financial Statement'!E5 -> 50724 | AX45: Revenue | BD45: 52444 | BF45: ='Common Size Financial Statement'!E5 -> 50724
D46: Long-term debt | J46: ='Common Size Financial Statement'!L34 -> 22881 | L46: ='Common Size Financial Statement'!N34 -> 22844 | O46: Total Liablities | U46: ='Common Size Financial Statement'!L43 -> 55349 | W46: ='Common Size Financial Statement'!N43 -> 50004 | Y46: Earning before Intrest & Tax(EBIT) | AE46: ='Common Size Financial Statement'!C13 -> 8702 | AG46: ='Common Size Financial Statement'!E13 -> 8303 | AM46: Total Average Assets | AS46: =142754/2 -> 71377 | AU46: =132465/2 -> 66232.5 | AX46: Total Average Fixed Assets | BD46: =20905/2 -> 10452.5 | BF46: =22620/2 -> 11310
D47: Equity | J47: ='Common Size Financial Statement'!L47 -> 19746 | L47: ='Common Size Financial Statement'!N47 -> 17655 | O47: Total Assets | U47: ='Common Size Financial Statement'!L24 -> 75095 | W47: ='Common Size Financial Statement'!N24 -> 67659 | Y47: Intrest | AE47: ='Common Size Financial Statement'!C14 -> 354 | AG47: ='Common Size Financial Statement'!E14 -> 505
G49: Long-term Debt / Equity | J49: =J46/J47 -> 1.1587663 | L49: =L46/L47 -> 1.2939111 | R49: Total liablities / Total Assets | U49: =U46/U47 -> 0.73705307 | W49: =W46/W47 -> 0.73905911 | AB49: Total liablities / Total Assets | AE49: =AE46/AE47 -> 24.581921 | AG49: =AG46/AG47 -> 16.441584 | AO49: Revenue/ Total average Assets | AS49: =AS45/AS46 -> 0.73474649 | AU49: =AU45/AU46 -> 0.76584758 | AZ49: Revenue/ Total FA average Assets | BD49: =BD45/BD46 -> 5.0173643 | BF49: =BF45/BF46 -> 4.4848806
AM54: Current Assets Turnover Ratio | AS54: Figures In Million | AW54: Inventory Turnover Ratio | BB54: Figures In Million
AS55: 2021 | AU55: 2020 | BB55: 2021 | BD55: 2020 | BE55: 2019
...

Sheet Ratio Analysis & Interpretation
B1: Unilever Group – Financial Ratio Analysis & Interpretation (2020 – 2021)
B4: 1. Profitability Analysis
B5: Ratios | O5: 2021 | P5: 2020
B6: Gross Profit Margin | O6: 0.42302265 | P6: 0.43450832 | Q6: =O6-P6 -> -0.011485667
B7: Operating Margin | O7: 0.16592937 | P7: 0.16368977 | Q7: =$O$7-$P$7 -> 0.0022396002
B8: Net Profit Margin | O8: 0.12624895 | P8: 0.11972636 | Q8: =O8-P8 -> 0.006522589
B9: ROCE | O9: 0.17294354 | P9: 0.1764081 | Q9: =O9-P9 -> -0.0034645611
B10: ROE | O10: 0.35404524 | P10: 0.38507387 | Q10: =O10-P10 -> -0.031028632
B11: Interpretation
B12: · Slight decline indicates mild cost pressure, though margins remain structurally strong within the competitive FMCG environment.
B13: · Marginal improvement reflects effective operating cost control and sustained efficiency across core business operations.
B14: · Increase suggests stronger bottom-line performance driven by improved expense control, operational discipline, and stable revenue generation during the financial year.
B15: · Stable capital returns indicate consistent efficiency in deploying long-term capital and generating healthy operating returns from invested funds.
B16: · Though slightly lower year-on-year, ROE remains at a strong level, highlighting sustained shareholder value creation and effective equity utilization within the business structure.
B20: 2. Efficiency & Working Capital Ratio | L20: 3. Liquidity & Solvency
B21: Ratios | H21: 2021 | I21: 2020 | L21: Ratios | O21: 2021 | P21: 2020
B22: Inventory Days | H22: 55 | I22: 55 | J22: =H22-I22 -> 0 | L22: Current Ratio | O22: 0.70227621 | P22: 0.7846251 | Q22: =O22-P22 -> -0.082348884
B23: Receivable Days | H23: 36 | I23: 42 | J23: =H23-I23 -> -6 | L23: Debt–Equity | O23: 1.1587663 | P23: 1.2939111 | Q23: =O23-P23 -> -0.13514474
B24: Payable Days | H24: 175 | I24: 177 | J24: =H24-I24 -> -2 | L24: Interest Coverage | O24: 24.581921 | P24: 16.441584 | Q24: =O24-P24 -> 8.1403367
B25: Asset Turnover | H25: 0.73 | I25: 0.77 | J25: =H25-I25 -> -0.04
B27: Interpretation | L27: Interpretation
B28: · Inventory holding period remained stable, reflecting consistent stock management efficiency. | L28: · Decline indicates tighter liquidity, though still manageable.
B29: · Improved collection cycle indicates stronger credit control and faster cash realization. | L29: · Lower leverage signals improving capital structure strength.
B30: · High payable period suggests strong supplier leverage and effective working capital financing. | L30: · Strong coverage reflects comfortable debt-servicing capacity despite decline.
B31: · Slight decline indicates marginal moderation in overall asset utilization efficiency.
D34: Overall Financial Assessment

Sheet Unilever Financial Performance 
A1: Unilever Group – Financial Performance Dashboard (2020 – 2021) FY 2020 - FY 2021
A28: → Margins remained resilient despite slight cost pressures. | H28: → Receivable collection improved while supplier credit remained strong.
